Workbook

Sheet Reservations
A1: Guest Name | B1: Listing | C1: Booking Source | D1: Confirmation Code | E1: Booking Date | F1: Check in Date | G1: Number of Nights | H1: Total Revenue | I1: Cleaning Fees | J1: Concierge Commission | K1: Revenue Net | L1: Frais Menage+comm | M1: Rentabilité | N1: Taux par nuit
A2: Meuble Apt 6 | B2: 6 | C2: Other | E2: 46023 | F2: 46023 | G2: 365 | H2: =850*12 -> 10200 | I2: 0 | J2: 0 | K2: =H2-I2-J2 -> 10200 | L2: =SUM(I2:J2) -> 0 | M2: =(H2-L2)/H2 -> 1 | N2: =K2/G2 -> 27.945205
A3: Jordan Peskerezh | B3: 8 | C3: Other | E3: 46023 | F3: 46023 | G3: 365 | H3: =500*12 -> 6000 | I3: 0 | J3: 0 | K3: =H3-I3-J3 -> 6000 | L3: =SUM(I3:J3) -> 0 | M3: =(H3-L3)/H3 -> 1 | N3: =K3/G3 -> 16.438356
A4: Daniel | B4: 2 | C4: AirBnb | F4: 46052 | G4: 3 | H4: 218.85 | I4: 85 | J4: =(H4-I4)*24% -> 32.124 | K4: =H4-I4-J4 -> 101.726 | L4: =SUM(I4:J4) -> 117.124 | M4: =(H4-L4)/H4 -> 0.46482065 | N4: =K4/G4 -> 33.908667
A5: Jean-Louis | B5: 2 | C5: AirBnb | E5: 46055 | F5: 46055 | G5: 3 | H5: 218.85 | I5: 85 | J5: =(H5-I5)*24% -> 32.124 | K5: =H5-I5-J5 -> 101.726 | L5: =SUM(I5:J5) -> 117.124 | M5: =(H5-L5)/H5 -> 0.46482065 | N5: =K5/G5 -> 33.908667
A6: Gabriel | B6: 5 | C6: AirBnb | E6: 46035 | F6: 46080 | G6: 2 | H6: 155.2 | I6: 65 | J6: =(H6-I6)*24% -> 21.648 | K6: =H6-I6-J6 -> 68.552 | L6: =SUM(I6:J6) -> 86.648 | M6: =(H6-L6)/H6 -> 0.44170103 | N6: =K6/G6 -> 34.276
A7: FG | B7: 5 | C7: FG Web Site | F7: 46043 | G7: 5 | H7: 300 | I7: 65 | J7: =(H7-I7)*24% -> 56.4 | K7: =H7-I7-J7 -> 178.6 | L7: =SUM(I7:J7) -> 121.4 | M7: =(H7-L7)/H7 -> 0.59533333 | N7: =K7/G7 -> 35.72
A8: Cecile | B8: 2 | C8: AirBnb | E8: 46047 | F8: 46059 | G8: 2 | H8: 181.67 | I8: 85 | J8: =(H8-I8)*24% -> 23.2008 | K8: =H8-I8-J8 -> 73.4692 | L8: =SUM(I8:J8) -> 108.2008 | M8: =(H8-L8)/H8 -> 0.40441019 | N8: =K8/G8 -> 36.7346
A9: Annaig | B9: 2 | C9: AirBnb | E9: 46089 | F9: 46101 | G9: 2 | H9: 215.47 | I9: 105 | J9: =(H9-I9)*24% -> 26.5128 | K9: =H9-I9-J9 -> 83.9572 | L9: =SUM(I9:J9) -> 131.5128 | M9: =(H9-L9)/H9 -> 0.38964682 | N9: =K9/G9 -> 41.9786
A10: Didier | B10: 5 | C10: AirBnb | E10: 46085 | F10: 46086 | G10: 3 | H10: 236.18 | I10: 65 | J10: =(H10-I10)*24% -> 41.0832 | K10: =H10-I10-J10 -> 130.0968 | L10: =SUM(I10:J10) -> 106.0832 | M10: =(H10-L10)/H10 -> 0.5508375 | N10: =K10/G10 -> 43.3656
A11: Cinema | B11: 2 | C11: FG Web Site | E11: 46060 | F11: 46074 | G11: 14 | H11: 890 | I11: 85 | J11: =(H11-I11)*24% -> 193.2 | K11: =H11-I11-J11 -> 611.8 | L11: =SUM(I11:J11) -> 278.2 | M11: =(H11-L11)/H11 -> 0.68741573 | N11: =K11/G11 -> 43.7
A12: Cinema | B12: 4 | C12: FG Web Site | E12: 46060 | F12: 46074 | G12: 14 | H12: 890 | I12: 85 | J12: =(H12-I12)*24% -> 193.2 | K12: =H12-I12-J12 -> 611.8 | L12: =SUM(I12:J12) -> 278.2 | M12: =(H12-L12)/H12 -> 0.68741573 | N12: =K12/G12 -> 43.7
A13: Julien | B13: 5 | C13: Leboncoin | E13: 46074 | F13: 46077 | G13: 2 | H13: 185 | I13: 65 | J13: =(H13-I13)*24% -> 28.8 | K13: =H13-I13-J13 -> 91.2 | L13: =SUM(I13:J13) -> 93.8 | M13: =(H13-L13)/H13 -> 0.49297297 | N13: =K13/G13 -> 45.6
A14: Marine | B14: 4 | C14: AirBnb | E14: 46060 | F14: 46097 | G14: 10 | H14: 720.5 | I14: 85 | J14: =(H14-I14)*24% -> 152.52 | K14: =H14-I14-J14 -> 482.98 | L14: =SUM(I14:J14) -> 237.52 | M14: =(H14-L14)/H14 -> 0.67034004 | N14: =K14/G14 -> 48.298
A15: Lorenz | B15: 4 | C15: AirBnb | E15: 46056 | F15: 46111 | G15: 7 | H15: 557.31 | I15: 85 | J15: =(H15-I15)*24% -> 113.3544 | K15: =H15-I15-J15 -> 358.9556 | L15: =SUM(I15:J15) -> 198.3544 | M15: =(H15-L15)/H15 -> 0.64408606 | N15: =K15/G15 -> 51.279371
A16: Veronique | B16: 2 | C16: AirBnb | E16: 46043 | F16: 46137 | G16: 8 | H16: 638.14 | I16: 85 | J16: =(H16-I16)*24% -> 132.7536 | K16: =H16-I16-J16 -> 420.3864 | L16: =SUM(I16:J16) -> 217.7536 | M16: =(H16-L16)/H16 -> 0.6587683 | N16: =K16/G16 -> 52.5483
A17: Worso | B17: 5 | C17: FG Web Site | E17: 46082 | F17: 46112 | G17: 9 | H17: 715 | I17: 85 | J17: =(H17-I17)*24% -> 151.2 | K17: =H17-I17-J17 -> 478.8 | L17: =SUM(I17:J17) -> 236.2 | M17: =(H17-L17)/H17 -> 0.66965035 | N17: =K17/G17 -> 53.2
A18: Audrey | B18: 2 | C18: AirBnb | E18: 46037 | F18: 46154 | G18: 6 | H18: 598.26 | I18: 120 | J18: =(H18-I18)*24% -> 114.7824 | K18: =H18-I18-J18 -> 363.4776 | L18: =SUM(I18:J18) -> 234.7824 | M18: =(H18-L18)/H18 -> 0.60755792 | N18: =K18/G18 -> 60.5796
A19: Christelle | B19: 2 | C19: AirBnb | E19: 46046 | F19: 46118 | G19: 12 | H19: 1043.15 | I19: 85 | J19: =(H19-I19)*24% -> 229.956 | K19: =H19-I19-J19 -> 728.194 | L19: =SUM(I19:J19) -> 314.956 | M19: =(H19-L19)/H19 -> 0.69807219 | N19: =K19/G19 -> 60.682833
... A34: Anna | B34: 4 | C34: AirBnb | E34: 46099 | F34: 46211 | G34: 14 | H34: 2087.84 | I34: 105 | J34: =(H34-I34)*24% -> 475.8816 | K34: =H34-I34-J34 -> 1506.9584 | L34: =SUM(I34:J34) -> 580.8816 | M34: =(H34-L34)/H34 -> 0.72177868 | N34: =K34/G34 -> 107.63989
A35: Siegfried | B35: 0 | C35: AirBnb | E35: 46084 | F35: 46086 | G35: 4 | H35: 560.56 | I35: 85 | K35: =H35-I35-J35 -> 475.56 | L35: =SUM(I35:J35) -> 85 | M35: =(H35-L35)/H35 -> 0.84836592 | N35: =K35/G35 -> 118.89
A36: Elisa | B36: 0 | C36: AirBnb | E36: 46049 | F36: 46053 | G36: 1 | H36: 202.44 | I36: 80 | K36: =H36-I36-J36 -> 122.44 | L36: =SUM(I36:J36) -> 80 | M36: =(H36-L36)/H36 -> 0.60482118 | N36: =K36/G36 -> 122.44
A37: Eva | B37: 0 | C37: AirBnb | E37: 46044 | F37: 46058 | G37: 1 | H37: 202.44 | I37: 80 | K37: =H37-I37-J37 -> 122.44 | L37: =SUM(I37:J37) -> 80 | M37: =(H37-L37)/H37 -> 0.60482118 | N37: =K37/G37 -> 122.44
A38: Manon | B38: 0 | C38: AirBnb | E38: 46033 | F38: 46067 | G38: 1 | H38: 202.44 | I38: 80 | K38: =H38-I38-J38 -> 122.44 | L38: =SUM(I38:J38) -> 80 | M38: =(H38-L38)/H38 -> 0.60482118 | N38: =K38/G38 -> 122.44
A39: Anthony | B39: 0 | C39: AirBnb | E39: 46079 | F39: 46081 | G39: 1 | H39: 202.44 | I39: 80 | K39: =H39-I39-J39 -> 122.44 | L39: =SUM(I39:J39) -> 80 | M39: =(H39-L39)/H39 -> 0.60482118 | N39: =K39/G39 -> 122.44
A40: Gisela | B40: 4 | C40: AirBnb | E40: 46049 | F40: 46244 | G40: 3 | H40: 573.58 | I40: 85 | J40: =(H40-I40)*24% -> 117.2592 | K40: =H40-I40-J40 -> 371.3208 | L40: =SUM(I40:J40) -> 202.2592 | M40: =(H40-L40)/H40 -> 0.64737404 | N40: =K40/G40 -> 123.7736
A41: Siegfried | B41: 0 | C41: AirBnb | E41: 46122 | F41: 46125 | G41: 4 | H41: 732.64 | I41: 80 | K41: =H41-I41-J41 -> 652.64 | L41: =SUM(I41:J41) -> 80 | M41: =(H41-L41)/H41 -> 0.89080585 | N41: =K41/G41 -> 163.16
A42: Siegfried | B42: 0 | C42: AirBnb | E42: 46126 | F42: 46132 | G42: 4 | H42: 732.64 | I42: 80 | K42: =H42-I42-J42 -> 652.64 | L42: =SUM(I42:J42) -> 80 | M42: =(H42-L42)/H42 -> 0.89080585 | N42: =K42/G42 -> 163.16
A43: Siegfried | B43: 0 | C43: AirBnb | E43: 46113 | F43: 46119 | G43: 3 | H43: 694.08 | I43: 80 | K43: =H43-I43-J43 -> 614.08 | L43: =SUM(I43:J43) -> 80 | M43: =(H43-L43)/H43 -> 0.88473951 | N43: =K43/G43 -> 204.69333
A44: Christelle | B44: 0 | C44: AirBnb | E44: 46067 | F44: 46230 | G44: 8 | H44: 2024.88 | I44: 120 | K44: =H44-I44-J44 -> 1904.88 | L44: =SUM(I44:J44) -> 120 | M44: =(H44-L44)/H44 -> 0.94073723 | N44: =K44/G44 -> 238.11
A45: Maxence | B45: 0 | C45: Website | E45: 46096 | F45: 46150 | G45: 2 | H45: 616.96 | I45: 120 | K45: =H45-I45-J45 -> 496.96 | L45: =SUM(I45:J45) -> 120 | M45: =(H45-L45)/H45 -> 0.80549793 | N45: =K45/G45 -> 248.48
A46: Anne | B46: 0 | C46: AirBnb | E46: 46021 | F46: 46206 | G46: 2 | H46: 616.96 | I46: 120 | K46: =H46-I46-J46 -> 496.96 | L46: =SUM(I46:J46) -> 120 | M46: =(H46-L46)/H46 -> 0.80549793 | N46: =K46/G46 -> 248.48
A47: Chloé | B47: 0 | C47: AirBnb | E47: 46070 | F47: 46242 | G47: 7 | H47: 1893.77 | I47: 120 | K47: =H47-I47-J47 -> 1773.77 | L47: =SUM(I47:J47) -> 120 | M47: =(H47-L47)/H47 -> 0.93663433 | N47: =K47/G47 -> 253.39571
A48: Mickael | B48: 0 | C48: AirBnb | E48: 46092 | F48: 46116 | G48: 2 | H48: 621.78 | I48: 85 | K48: =H48-I48-J48 -> 536.78 | L48: =SUM(I48:J48) -> 85 | M48: =(H48-L48)/H48 -> 0.8632957 | N48: =K48/G48 -> 268.39
A49: Magali | B49: 0 | C49: Leboncoin | E49: 46027 | F49: 46143 | G49: 2 | H49: 706.4 | I49: 120 | K49: =H49-I49-J49 -> 586.4 | L49: =SUM(I49:J49) -> 120 | M49: =(H49-L49)/H49 -> 0.83012458 | N49: =K49/G49 -> 293.2
A50: Virginie | B50: 0 | C50: Website | E50: 46068 | F50: 46165 | G50: 2 | H50: 667.4 | I50: 80 | K50: =H50-I50-J50 -> 587.4 | L50: =SUM(I50:J50) -> 80 | M50: =(H50-L50)/H50 -> 0.88013186 | N50: =K50/G50 -> 293.7
A51: Benoit | B51: 0 | C51: Website | E51: 46068 | F51: 46155 | G51: 4 | H51: 1292.8 | I51: 80 | K51: =H51-I51-J51 -> 1212.8 | L51: =SUM(I51:J51) -> 80 | M51: =(H51-L51)/H51 -> 0.93811881 | N51: =K51/G51 -> 303.2
A52: Maud | B52: 2 | C52: AirBnb | E52: 46134 | F52: 46237 | G52: 3 | H52: 621.07 | I52: 105 | J52: =(H52-I52)*24% -> 123.8568 | K52: =H52-I52-J52 -> 392.2132 | L52: =SUM(I52:J52) -> 228.8568 | M52: =(H52-L52)/H52 -> 0.63151207 | N52: =K52/G52 -> 130.73773
A53: Marie | B53: 4 | C53: AirBnb | E53: 46132 | F53: 46133 | G53: 3 | H53: 332.58 | I53: 105 | J53: =(H53-I53)*24% -> 54.6192 | K53: =H53-I53-J53 -> 172.9608 | L53: =SUM(I53:J53) -> 159.6192 | M53: =(H53-L53)/H53 -> 0.52005773 | N53: =K53/G53 -> 57.6536
A54: Lucie | B54: 2 | C54: AirBnb | E54: 46131 | F54: 46134 | G54: 2 | H54: 283.07 | I54: 105 | J54: =(H54-I54)*24% -> 42.7368 | K54: =H54-I54-J54 -> 135.3332 | L54: =SUM(I54:J54) -> 147.7368 | M54: =(H54-L54)/H54 -> 0.47809093 | N54: =K54/G54 -> 67.6666
...

Sheet Variable Expenses
A1: Description | B1: Listing | C1: Type | D1: 2026-01 | E1: 2026-02 | F1: 2026-03 | G1: 2026-04 | H1: 2026-05 | I1: 2026-06 | J1: 2026-07 | K1: 2026-08 | L1: 2026-09 | M1: 2026-10 | N1: 2026-11 | O1: 2026-12
A2: Electricité | B2: 2 | C2: estimate | D2: 150 | E2: 150 | F2: 150 | G2: 150 | H2: 80 | I2: 40 | J2: 40 | K2: 40 | L2: 40 | M2: 80 | N2: 150 | O2: 150
A3: Electricité | B3: 2 | C3: actual | D3: 123 | E3: 150
A4: Electricité | B4: 4 | C4: estimate | D4: 150 | E4: 150 | F4: 150 | G4: 150 | H4: 80 | I4: 40 | J4: 40 | K4: 40 | L4: 40 | M4: 80 | N4: 150 | O4: 150
A5: Electricité | B5: 5 | C5: estimate | D5: 150 | E5: 150 | F5: 150 | G5: 150 | H5: 80 | I5: 40 | J5: 40 | K5: 40 | L5: 40 | M5: 80 | N5: 150 | O5: 150
A6: Electricité | B6: 6 | C6: estimate | D6: 0 | E6: 0 | F6: 0 | G6: 0 | H6: 0 | I6: 0 | J6: 0 | K6: 0 | L6: 0 | M6: 0 | N6: 0 | O6: 0
A7: Electricité | B7: 0 | C7: estimate | D7: 150 | E7: 150 | F7: 150 | G7: 150 | H7: 150 | I7: 80 | J7: 80 | K7: 80 | L7: 80 | M7: 80 | N7: 150 | O7: 150
A8: Electricité | B8: 8 | C8: estimate | D8: 80 | E8: 50 | F8: 50 | G8: 50 | H8: 50 | I8: 30 | J8: 30 | K8: 30 | L8: 30 | M8: 50 | N8: 50 | O8: 80
A9: Electricité | B9: 7 | C9: estimate | D9: 30 | E9: 30 | F9: 30 | G9: 30 | H9: 30 | I9: 30 | J9: 30 | K9: 30 | L9: 30 | M9: 30 | N9: 30 | O9: 30
A10: Fuel | B10: 0 | C10: estimate | D10: 300 | E10: 300 | F10: 300 | G10: 200 | H10: 0 | I10: 0 | J10: 0 | K10: 0 | L10: 0 | M10: 0 | N10: 300 | O10: 300

Sheet Fixed Expenses
A1: Description | B1: Listing | C1: 2026-01 | D1: 2026-02 | E1: 2026-03 | F1: 2026-04 | G1: 2026-05 | H1: 2026-06 | I1: 2026-07 | J1: 2026-08 | K1: 2026-09 | L1: 2026-10 | M1: 2026-11 | N1: 2026-12
A2: Mensualité Prêt | B2: 0 | C2: 500 | D2: 500 | E2: 500 | F2: 500 | G2: 500 | H2: 500 | I2: 500 | J2: 500 | K2: 500 | L2: 500 | M2: 500 | N2: 500
A3: Mensualité Prêt | B3: 8 | C3: 158 | D3: 158 | E3: 158 | F3: 158 | G3: 158 | H3: 158 | I3: 158 | J3: 158 | K3: 158 | L3: 158 | M3: 158 | N3: 158
A4: Mensualité Prêt | B4: 2 | C4: =1250*Lookups!F25 -> 350.21552 | D4: =C4 -> 350.21552 | E4: =D4 -> 350.21552 | F4: =E4 -> 350.21552 | G4: =F4 -> 350.21552 | H4: =G4 -> 350.21552 | I4: =H4 -> 350.21552 | J4: =I4 -> 350.21552 | K4: =J4 -> 350.21552 | ... N4: =M4 -> 350.21552
A5: Mensualité Prêt | B5: 4 | C5: =1250*Lookups!F26 -> 226.2931 | D5: =C5 -> 226.2931 | E5: =D5 -> 226.2931 | F5: =E5 -> 226.2931 | G5: =F5 -> 226.2931 | H5: =G5 -> 226.2931 | I5: =H5 -> 226.2931 | J5: =I5 -> 226.2931 | K5: =J5 -> 226.2931 | ... N5: =M5 -> 226.2931
A6: Mensualité Prêt | B6: 5 | C6: =1250*Lookups!F27 -> 145.47414 | D6: =C6 -> 145.47414 | E6: =D6 -> 145.47414 | F6: =E6 -> 145.47414 | G6: =F6 -> 145.47414 | H6: =G6 -> 145.47414 | I6: =H6 -> 145.47414 | J6: =I6 -> 145.47414 | K6: =J6 -> 145.47414 | ... N6: =M6 -> 145.47414
A7: Mensualité Prêt | B7: 6 | C7: =1250*Lookups!F28 -> 206.53736 | D7: =C7 -> 206.53736 | E7: =D7 -> 206.53736 | F7: =E7 -> 206.53736 | G7: =F7 -> 206.53736 | H7: =G7 -> 206.53736 | I7: =H7 -> 206.53736 | J7: =I7 -> 206.53736 | K7: =J7 -> 206.53736 | ... N7: =M7 -> 206.53736
A8: Mensualité Prêt | B8: 7 | C8: =1250*Lookups!F29 -> 321.47989 | D8: =C8 -> 321.47989 | E8: =D8 -> 321.47989 | F8: =E8 -> 321.47989 | G8: =F8 -> 321.47989 | H8: =G8 -> 321.47989 | I8: =H8 -> 321.47989 | J8: =I8 -> 321.47989 | K8: =J8 -> 321.47989 | ... N8: =M8 -> 321.47989
A9: Charges Copro | B9: 2 | C9: 93 | D9: 93 | E9: 93 | F9: 93 | G9: 93 | H9: 93 | I9: 93 | J9: 93 | K9: 93 | L9: 93 | M9: 93 | N9: 93
A10: Charges Copro | B10: 4 | C10: 62 | D10: 62 | E10: 62 | F10: 62 | G10: 62 | H10: 62 | I10: 62 | J10: 62 | K10: 62 | L10: 62 | M10: 62 | N10: 62
A11: Charges Copro | B11: 5 | C11: 40 | D11: 40 | E11: 40 | F11: 40 | G11: 40 | H11: 40 | I11: 40 | J11: 40 | K11: 40 | L11: 40 | M11: 40 | N11: 40
A12: Charges Copro | B12: 6 | C12: 57 | D12: 57 | E12: 57 | F12: 57 | G12: 57 | H12: 57 | I12: 57 | J12: 57 | K12: 57 | L12: 57 | M12: 57 | N12: 57
A13: Charges Copro | B13: 7 | C13: 47 | D13: 47 | E13: 47 | F13: 47 | G13: 47 | H13: 47 | I13: 47 | J13: 47 | K13: 47 | L13: 47 | M13: 47 | N13: 47
A14: CFE | B14: 2 | C14: 20 | D14: 20 | E14: 20 | F14: 20 | G14: 20 | H14: 20 | I14: 20 | J14: 20 | K14: 20 | L14: 20 | M14: 20 | N14: 20
A15: CFE | B15: 4 | C15: 20 | D15: 20 | E15: 20 | F15: 20 | G15: 20 | H15: 20 | I15: 20 | J15: 20 | K15: 20 | L15: 20 | M15: 20 | N15: 20
A16: CFE | B16: 5 | C16: 20 | D16: 20 | E16: 20 | F16: 20 | G16: 20 | H16: 20 | I16: 20 | J16: 20 | K16: 20 | L16: 20 | M16: 20 | N16: 20
A17: CFE | B17: 6 | C17: 20 | D17: 20 | E17: 20 | F17: 20 | G17: 20 | H17: 20 | I17: 20 | J17: 20 | K17: 20 | L17: 20 | M17: 20 | N17: 20
A18: CFE | B18: 7 | C18: 20 | D18: 20 | E18: 20 | F18: 20 | G18: 20 | H18: 20 | I18: 20 | J18: 20 | K18: 20 | L18: 20 | M18: 20 | N18: 20
A19: CFE | B19: 8 | C19: 20 | D19: 20 | E19: 20 | F19: 20 | G19: 20 | H19: 20 | I19: 20 | J19: 20 | K19: 20 | L19: 20 | M19: 20 | N19: 20
A20: CFE | B20: 0 | C20: 20 | D20: 20 | E20: 20 | F20: 20 | G20: 20 | H20: 20 | I20: 20 | J20: 20 | K20: 20 | L20: 20 | M20: 20 | N20: 20
... A27: Jardin | B27: 7 | C27: 12 | D27: 12 | E27: 12 | F27: 12 | G27: 12 | H27: 12 | I27: 12 | J27: 12 | K27: 12 | L27: 12 | M27: 12 | N27: 12
A28: Compta | B28: 2 | C28: =1800/6/12 -> 25 | D28: =1800/6/12 -> 25 | E28: =1800/6/12 -> 25 | F28: =1800/6/12 -> 25 | G28: =1800/6/12 -> 25 | H28: =1800/6/12 -> 25 | I28: =1800/6/12 -> 25 | J28: =1800/6/12 -> 25 | ... N28: =1800/6/12 -> 25
A29: Compta | B29: 4 | C29: =1800/6/12 -> 25 | D29: =1800/6/12 -> 25 | E29: =1800/6/12 -> 25 | F29: =1800/6/12 -> 25 | G29: =1800/6/12 -> 25 | H29: =1800/6/12 -> 25 | I29: =1800/6/12 -> 25 | J29: =1800/6/12 -> 25 | ... N29: =1800/6/12 -> 25
A30: Compta | B30: 5 | C30: =1800/6/12 -> 25 | D30: =1800/6/12 -> 25 | E30: =1800/6/12 -> 25 | F30: =1800/6/12 -> 25 | G30: =1800/6/12 -> 25 | H30: =1800/6/12 -> 25 | I30: =1800/6/12 -> 25 | J30: =1800/6/12 -> 25 | ... N30: =1800/6/12 -> 25
A31: Compta | B31: 6 | C31: =1800/6/12 -> 25 | D31: =1800/6/12 -> 25 | E31: =1800/6/12 -> 25 | F31: =1800/6/12 -> 25 | G31: =1800/6/12 -> 25 | H31: =1800/6/12 -> 25 | I31: =1800/6/12 -> 25 | J31: =1800/6/12 -> 25 | ... N31: =1800/6/12 -> 25
A32: Compta | B32: 0 | C32: =1800/6/12 -> 25 | D32: =1800/6/12 -> 25 | E32: =1800/6/12 -> 25 | F32: =1800/6/12 -> 25 | G32: =1800/6/12 -> 25 | H32: =1800/6/12 -> 25 | I32: =1800/6/12 -> 25 | J32: =1800/6/12 -> 25 | ... N32: =1800/6/12 -> 25
A33: Compta | B33: 8 | C33: =1800/6/12 -> 25 | D33: =1800/6/12 -> 25 | E33: =1800/6/12 -> 25 | F33: =1800/6/12 -> 25 | G33: =1800/6/12 -> 25 | H33: =1800/6/12 -> 25 | I33: =1800/6/12 -> 25 | J33: =1800/6/12 -> 25 | ... N33: =1800/6/12 -> 25
A34: Taxe foncieres | B34: 2 | C34: 35 | D34: 35 | E34: 35 | F34: 35 | G34: 35 | H34: 35 | I34: 35 | J34: 35 | K34: 35 | L34: 35 | M34: 35 | N34: 35
A35: Taxe foncieres | B35: 4 | C35: 35 | D35: 35 | E35: 35 | F35: 35 | G35: 35 | H35: 35 | I35: 35 | J35: 35 | K35: 35 | L35: 35 | M35: 35 | N35: 35
A36: Taxe foncieres | B36: 5 | C36: 35 | D36: 35 | E36: 35 | F36: 35 | G36: 35 | H36: 35 | I36: 35 | J36: 35 | K36: 35 | L36: 35 | M36: 35 | N36: 35
A37: Taxe foncieres | B37: 6 | C37: 35 | D37: 35 | E37: 35 | F37: 35 | G37: 35 | H37: 35 | I37: 35 | J37: 35 | K37: 35 | L37: 35 | M37: 35 | N37: 35
A38: Taxe foncieres | B38: 0 | C38: 50 | D38: 50 | E38: 50 | F38: 50 | G38: 50 | H38: 50 | I38: 50 | J38: 50 | K38: 50 | L38: 50 | M38: 50 | N38: 50
A39: Tax Habitation | B39: 5 | C39: 35 | D39: 35 | E39: 35 | F39: 35 | G39: 35 | H39: 35 | I39: 35 | J39: 35 | K39: 35 | L39: 35 | M39: 35 | N39: 35
A40: Electricité abonnement | B40: 2 | C40: 16 | D40: 16 | E40: 16 | F40: 16 | G40: 16 | H40: 16 | I40: 16 | J40: 16 | K40: 16 | L40: 16 | M40: 16 | N40: 16
A41: Electricité abonnement | B41: 4 | C41: 16 | D41: 16 | E41: 16 | F41: 16 | G41: 16 | H41: 16 | I41: 16 | J41: 16 | K41: 16 | L41: 16 | M41: 16 | N41: 16
A42: Electricité abonnement | B42: 5 | C42: 16 | D42: 16 | E42: 16 | F42: 16 | G42: 16 | H42: 16 | I42: 16 | J42: 16 | K42: 16 | L42: 16 | M42: 16 | N42: 16
A43: Electricité abonnement | B43: 7 | C43: 16 | D43: 16 | E43: 16 | F43: 16 | G43: 16 | H43: 16 | I43: 16 | J43: 16 | K43: 16 | L43: 16 | M43: 16 | N43: 16
A44: Electricité abonnement | B44: 0 | C44: 16 | D44: 16 | E44: 16 | F44: 16 | G44: 16 | H44: 16 | I44: 16 | J44: 16 | K44: 16 | L44: 16 | M44: 16 | N44: 16

Sheet Pricing Rules
A1: rule_id | B1: property_id | C1: start_date | D1: end_date | E1: nightly_price | F1: cleaning_fee | G1: min_nights
A2: 50 | B2: 5 | C2: 46113 | D2: 46203 | E2: 68 | F2: 65 | G2: 1
A3: 51 | B3: 5 | C3: 46204 | D3: 46265 | E3: 130 | F3: 85 | G3: 2
A4: 40 | B4: 4 | C4: 46113 | D4: 46203 | E4: 85 | F4: 105 | G4: 2
A5: 41 | B5: 4 | C5: 46204 | D5: 46265 | E5: 130 | F5: 105 | G5: 5
A6: 20 | B6: 2 | C6: 46113 | D6: 46203 | E6: 130 | F6: 105 | G6: 2
A7: 21 | B7: 2 | C7: 46204 | D7: 46265 | E7: 140 | F7: 105 | G7: 5
A8: 0 | B8: 0 | C8: 46113 | D8: 46203 | E8: 190 | F8: 120 | G8: 1
A9: 1 | B9: 0 | C9: 46204 | D9: 46234 | E9: 230 | F9: 120 | G9: 3
A10: 2 | B10: 0 | C10: 46235 | D10: 46265 | E10: 260 | F10: 120 | G10: 3
A11: 3 | B11: 0 | C11: 46266 | D11: 46741 | E11: 190 | F11: 120 | G11: 2

Sheet Leads
A1: created_at | B1: status | C1: property_id | D1: check_in | E1: check_out | F1: nights | G1: guests | H1: currency | I1: accommodation_total | J1: cleaning_fee | K1: taxe_de_sejour | L1: quoted_total | M1: name | N1: email | O1: phone | P1: message | Q1: gdpr_consent | R1: country | S1: city | T1: timezone | U1: source_url | V1: user_agent
A2: 2026-05-23T18:52:50.741Z | B2: notified | C2: 2 | D2: 46215 | E2: 46222 | F2: 7 | G2: 4 | H2: EUR | I2: 1050 | J2: 85 | K2: 141.4 | L2: 1276.4 | M2: Test User | N2: test@example.com | O2: 600000000 | P2: Test lead | Q2: TRUE | R2: US | S2: Charlotte | T2: America/New_York | U2: test | V2: curl/8.7.1
A3: 2026-05-23T18:57:38.633Z | B3: notified | C3: 5 | D3: 46169 | E3: 46171 | F3: 2 | G3: 2 | H3: EUR | I3: 300 | J3: 85 | K3: 15 | L3: 400 | M3: Daniel Haque | N3: dhaque@gmail.com | O3: 6786786 | P3: test 123 | Q3: TRUE | R3: US | S3: Charlotte | T3: America/New_York | U3: https://widget.leclosdelavoilerie.com/ | V3: Mozilla/5.0 (Macintosh; Intel Mac OS X 10_15_7) AppleWebKit/537.36 (KHTML, like Gecko) Chrome/147.0.0.0 Safari/537.36
A4: 2026-05-23T19:07:26.306Z | B4: notified | C4: 5 | D4: 46176 | E4: 46184 | F4: 8 | G4: 2 | H4: EUR | I4: 1200 | J4: 85 | K4: 60 | L4: 1345 | M4: Test mister | N4: dhaque@gmail.com | O4: 798798 | P4: yeahg baby | Q4: TRUE | R4: US | S4: Charlotte | T4: America/New_York | U4: https://widget.leclosdelavoilerie.com/ | V4: Mozilla/5.0 (Macintosh; Intel Mac OS X 10_15_7) AppleWebKit/537.36 (KHTML, like Gecko) Chrome/147.0.0.0 Safari/537.36
A5: 2026-05-23T19:16:01.861Z | B5: notified | C5: 5 | D5: 46169 | E5: 46172 | F5: 3 | G5: 2 | H5: EUR | I5: 450 | J5: 85 | K5: 22.5 | L5: 557.5 | M5: Aurore | N5: aurorefourrier@hotmail.fr | O5: 7897689 | P5: hey babe | Q5: TRUE | R5: US | S5: Charlotte | T5: America/New_York | U5: https://widget.leclosdelavoilerie.com/?property_id=5 | V5: Mozilla/5.0 (Macintosh; Intel Mac OS X 10_15_7) AppleWebKit/537.36 (KHTML, like Gecko) Chrome/147.0.0.0 Safari/537.36
A6: 2026-05-23T20:29:22.734Z | B6: notified | C6: 0 | D6: 46188 | E6: 46191 | F6: 3 | G6: 4 | H6: EUR | I6: 570 | J6: 120 | K6: 28.5 | L6: 718.5 | M6: Leopold Haque | N6: aurorefourrier@hotmail.fr | O6: 687687 | P6: baby | Q6: TRUE | R6: US | S6: Charlotte | T6: America/New_York | U6: https://widget.leclosdelavoilerie.com/?property_id=0 | V6: Mozilla/5.0 (Macintosh; Intel Mac OS X 10_15_7) AppleWebKit/605.1.15 (KHTML, like Gecko) Version/26.3.1 Safari/605.1.15
A7: 2026-05-24T00:47:40.274Z | B7: notified | C7: 4 | D7: 46169 | E7: 46172 | F7: 3 | G7: 2 | H7: EUR | I7: 255 | J7: 105 | K7: 12.75 | L7: 372.75 | M7: Danny boy | N7: dhaque@gmail.com | O7: 787889 | P7: just a test | Q7: TRUE | R7: US | S7: Charlotte | T7: America/New_York | U7: https://widget.leclosdelavoilerie.com/?portfolio=voilerie | V7: Mozilla/5.0 (Macintosh; Intel Mac OS X 10_15_7) AppleWebKit/537.36 (KHTML, like Gecko) Chrome/147.0.0.0 Safari/537.36

Sheet Widget Settings
A1: key | B1: value
A2: default_currency | B2: EUR
A3: default_language | B3: fr
A4: default_min_nights | B4: 2
A5: booking_email_to | B5: dhaque@gmail.com
A6: lead_status_default | B6: new
A7: quote_valid_hours | B7: 24
A8: show_cleaning_fee | B8: TRUE
A9: allow_hold_request | B9: FALSE
A10: max_guests_default | B10: 6
A11: direct_booking_message | B11: Demande envoyée — nous revenons vers vous rapidement.

Sheet Monthly Targets
A1: Month | B1: Year | C1: 0 | D1: 2 | E1: 4 | F1: 5
A2: 1 | B2: 2026 | C2: =130*0.1*30 -> 390 | D2: =0.5*30*40 -> 600 | E2: =0.5*30*35 -> 525 | F2: =0.5*30*30 -> 450
A3: 2 | B3: 2026 | C3: =130*0.1*30 -> 390 | D3: =0.5*30*40 -> 600 | E3: =0.5*30*35 -> 525 | F3: =0.5*30*30 -> 450
A4: 3 | B4: 2026 | C4: =130*0.1*30 -> 390 | D4: =0.5*30*40 -> 600 | E4: =0.5*30*35 -> 525 | F4: =0.5*30*30 -> 450
A5: 4 | B5: 2026 | C5: =150*0.6*30 -> 2700 | D5: =0.5*30*90 -> 1350 | E5: =0.5*30*80 -> 1200 | F5: =0.5*30*60 -> 900
A6: 5 | B6: 2026 | C6: =160*0.6*30 -> 2880 | D6: =0.5*30*90 -> 1350 | E6: =0.5*30*80 -> 1200 | F6: =0.5*30*60 -> 900
A7: 6 | B7: 2026 | C7: =150*30 -> 4500 | D7: =0.5*30*90 -> 1350 | E7: =0.5*30*80 -> 1200 | F7: =0.5*30*60 -> 900
A8: 7 | B8: 2026 | C8: =220*30 -> 6600 | D8: =115*31 -> 3565 | E8: =105*30 -> 3150 | F8: =85*30 -> 2550
A9: 8 | B9: 2026 | C9: =220*30 -> 6600 | D9: =115*31 -> 3565 | E9: =105*30 -> 3150 | F9: =85*30 -> 2550
A10: 9 | B10: 2026 | C10: =190*0.5*30 -> 2850 | D10: =95*0.8*30 -> 2280 | E10: =85*0.8*30 -> 2040 | F10: =65*0.8*30 -> 1560
A11: 10 | B11: 2026 | C11: =150+0.1*30 -> 153 | D11: =0.6*30*40 -> 720 | E11: =0.6*30*35 -> 630 | F11: =0.6*30*30 -> 540
A12: 11 | B12: 2026 | C12: =150+0.1*30 -> 153 | D12: =0.6*30*40 -> 720 | E12: =0.6*30*35 -> 630 | F12: =0.6*30*30 -> 540
A13: 12 | B13: 2026 | C13: =0.1*220*30 -> 660 | D13: =0.5*30*40 -> 600 | E13: =0.5*30*35 -> 525 | F13: =0.5*30*30 -> 450
A15: Sum | C15: =SUM(C2:C13) -> 28266 | D15: =SUM(D2:D13) -> 17300 | E15: =SUM(E2:E13) -> 15300 | F15: =SUM(F2:F13) -> 12240

Sheet Lookups
A1: Listings
A3: 0 | B3: Grande maison de famille avec piscine
A4: 4 | B4: Un balcon sur la mer
A5: 2 | B5: Les pieds dans l’eau
A6: 5 | B6: Apartment 5
A7: 6 | B7: Apartment 6
A8: 7 | B8: Annexe
A9: 8 | B9: Apartment Plozevet
A11: Source | B11: AirBnb
B12: FG Website
B13: LeBonCoin
B14: Website
B15: Other
A22: Milliemes
A23: Lots | B23: Milliemes de Charges generale | E23: listing | F23: %
A24: 1 | B24: 142
A25: 2 | B25: 180 | E25: 2 | F25: =(B25+B32)/B38 -> 0.28017241
A26: 3 | B26: 87 | E26: 4 | F26: =B27/B38 -> 0.18103448
A27: 4 | B27: 126 | E27: 5 | F27: =B28/B38 -> 0.11637931
A28: 5 | B28: 81 | E28: 6 | F28: =B29/B38 -> 0.16522989
A29: 6 | B29: 115 | E29: 7 | F29: =B30/B38 -> 0.25718391
A30: 7 | B30: 179
A31: 8 | B31: 15
A32: 9 | B32: 15
A33: 10 | B33: 15
A34: 11 | B34: 15
A35: 12 | B35: 15
A36: 13 | B36: 15
A38: Total ours | B38: =B25+B27+B28+B29+B30+B31 -> 696

Sheet Listings
A1: Listing | B1: Name | C1: Description AirBnB | D1: Group
A2: 0 | B2: La Peskerezh | C2: Grande maison de famille avec piscine | D2: Peskerezh
A3: 4 | B3: Voilerie 4 | C3: Un balcon sur la mer | D3: Voilerie
A4: 2 | B4: Voilerie 2 | C4: Un jardin sur la mer | D4: Voilerie
A5: 5 | B5: Voilerie 5 | C5: Les pieds dans l’eau | D5: Voilerie
A6: 6 | B6: Voilerie 6 | C6: Voilerie 6 | D6: VoilerieOther
A7: 7 | B7: Voilerie Annexe | C7: Annexe | D7: Voilerie
A8: 8 | B8: Apartment La Peskerezh | C8: Apartment Plozevet | D8: Peskerezh

Sheet Market Listings
A1: active | B1: listing_id | C1: listing_name | D1: type | E1: source | F1: airbnb_id | G1: portfolio | H1: notes
A2: TRUE | B2: 4 | C2: Voilerie 4 | D2: own | E2: airbnb | F2: 1445081161439839662 | G2: Voilerie
A3: TRUE | B3: c1 | C3: Philippe Tessier | D3: competitor | E3: airbnb | F3: 1634147360136656154
A4: TRUE | B4: c2 | C4: Trescadec | D4: competitor | E4: airbnb | F4: 14884205
A5: TRUE | B5: 2 | C5: Voilerie 2 | D5: own | E5: airbnb | F5: 1575129991787890434
A6: TRUE | B6: 5 | C6: Voilerie 5 | D6: own | E6: airbnb | F6: 1434608008789009131
A7: TRUE | B7: c3 | C7: Sea view & Port d'Audierne | D7: competitor | E7: airbnb | F7: 1370286702062952676
A8: TRUE | B8: c4 | C8: House combining old and contemporary with garden | D8: competitor | E8: airbnb | F8: 45538206

Sheet Market Competitor Sets
A1: own_listing_id | B1: competitor_listing_id | C1: expected_price_index | D1: active | E1: notes
A2: 2 | B2: c1 | C2: 0.8 | D2: TRUE | E2: competitor should be 20% cheaper

Sheet Market Scenarios
A1: active | B1: scenario_id | C1: mode | D1: horizon_count | E1: month_start_offset | F1: nights | G1: adults | H1: children | I1: infants | J1: pets | K1: checkin_weekday
A2: TRUE | B2: weekly_7n | C2: weekly | D2: 4 | E2: 1 | F2: 7 | G2: 2 | H2: 1 | I2: 0 | J2: 0 | K2: Saturday
A3: TRUE | B3: monthly_7n | C3: weekly | D3: 7 | E3: 2 | F3: 7 | G3: 2 | H3: 1 | I3: 0 | J3: 0 | K3: Saturday

Sheet Market Settings
A1: key | B1: value
A2: apify_actor_id | B2: sve/airbnb-price-scraper
A3: max_scrapes_per_run | B3: 50
A4: alert_price_change_pct | B4: 10
A5: output_folder | B5: data/market
